Traceback (most recent call last):
  File "/Library/Frameworks/Python.framework/Versions/3.10/lib/python3.10/site-packages/jupyter_cache/executors/utils.py", line 51, in single_nb_execution
    executenb(
  File "/Library/Frameworks/Python.framework/Versions/3.10/lib/python3.10/site-packages/nbclient/client.py", line 1204, in execute
    return NotebookClient(nb=nb, resources=resources, km=km, **kwargs).execute()
  File "/Library/Frameworks/Python.framework/Versions/3.10/lib/python3.10/site-packages/nbclient/util.py", line 84, in wrapped
    return just_run(coro(*args, **kwargs))
  File "/Library/Frameworks/Python.framework/Versions/3.10/lib/python3.10/site-packages/nbclient/util.py", line 62, in just_run
    return loop.run_until_complete(coro)
  File "/Library/Frameworks/Python.framework/Versions/3.10/lib/python3.10/asyncio/base_events.py", line 646, in run_until_complete
    return future.result()
  File "/Library/Frameworks/Python.framework/Versions/3.10/lib/python3.10/site-packages/nbclient/client.py", line 663, in async_execute
    await self.async_execute_cell(
  File "/Library/Frameworks/Python.framework/Versions/3.10/lib/python3.10/site-packages/nbclient/client.py", line 965, in async_execute_cell
    await self._check_raise_for_error(cell, cell_index, exec_reply)
  File "/Library/Frameworks/Python.framework/Versions/3.10/lib/python3.10/site-packages/nbclient/client.py", line 862, in _check_raise_for_error
    raise CellExecutionError.from_cell_and_msg(cell, exec_reply_content)
nbclient.exceptions.CellExecutionError: An error occurred while executing the following cell:
------------------
FILE_URL = "https://archive.ics.uci.edu/ml/machine-learning-databases/00240/UCI%20HAR%20Dataset.zip"
FILE_NAME = "UCI HAR Dataset.zip"
DATA_PATH = Path("../../../data/large_files")

load_har_dataset(url=FILE_URL, extract_path=DATA_PATH, filename=FILE_NAME)

PATH_TO_SAMSUNG_DATA = DATA_PATH / FILE_NAME.strip('.zip')
------------------

[0;31m---------------------------------------------------------------------------[0m
[0;31mFileNotFoundError[0m                         Traceback (most recent call last)
Input [0;32mIn [3][0m, in [0;36m<cell line: 5>[0;34m()[0m
[1;32m      2[0m FILE_NAME [38;5;241m=[39m [38;5;124m"[39m[38;5;124mUCI HAR Dataset.zip[39m[38;5;124m"[39m
[1;32m      3[0m DATA_PATH [38;5;241m=[39m Path([38;5;124m"[39m[38;5;124m../../../data/large_files[39m[38;5;124m"[39m)
[0;32m----> 5[0m [43mload_har_dataset[49m[43m([49m[43murl[49m[38;5;241;43m=[39;49m[43mFILE_URL[49m[43m,[49m[43m [49m[43mextract_path[49m[38;5;241;43m=[39;49m[43mDATA_PATH[49m[43m,[49m[43m [49m[43mfilename[49m[38;5;241;43m=[39;49m[43mFILE_NAME[49m[43m)[49m
[1;32m      7[0m PATH_TO_SAMSUNG_DATA [38;5;241m=[39m DATA_PATH [38;5;241m/[39m FILE_NAME[38;5;241m.[39mstrip([38;5;124m'[39m[38;5;124m.zip[39m[38;5;124m'[39m)

Input [0;32mIn [2][0m, in [0;36mload_har_dataset[0;34m(url, extract_path, filename, overwrite)[0m
[1;32m      8[0m [38;5;28mprint[39m([38;5;124m"[39m[38;5;124mDownloading the dataset from:  [39m[38;5;124m"[39m, url)
[1;32m      9[0m response [38;5;241m=[39m requests[38;5;241m.[39mget(url)
[0;32m---> 11[0m [38;5;28;01mwith[39;00m [38;5;28;43mopen[39;49m[43m([49m[43mfilepath[49m[43m,[49m[43m [49m[38;5;124;43m'[39;49m[38;5;124;43mwb[39;49m[38;5;124;43m'[39;49m[43m)[49m [38;5;28;01mas[39;00m f:
[1;32m     12[0m     f[38;5;241m.[39mwrite(response[38;5;241m.[39mcontent)
[1;32m     14[0m [38;5;28;01mwith[39;00m ZipFile(filepath, [38;5;124m'[39m[38;5;124mr[39m[38;5;124m'[39m) [38;5;28;01mas[39;00m zipObj:
[1;32m     15[0m     [38;5;66;03m# Extract all the contents of zip file in current directory[39;00m

[0;31mFileNotFoundError[0m: [Errno 2] No such file or directory: '../../../data/large_files/UCI HAR Dataset.zip'
FileNotFoundError: [Errno 2] No such file or directory: '../../../data/large_files/UCI HAR Dataset.zip'

