Traceback (most recent call last):
  File "/Users/kashnitskiyy/opt/anaconda3/envs/mlcourse/lib/python3.8/site-packages/jupyter_cache/executors/utils.py", line 51, in single_nb_execution
    executenb(
  File "/Users/kashnitskiyy/opt/anaconda3/envs/mlcourse/lib/python3.8/site-packages/nbclient/client.py", line 1093, in execute
    return NotebookClient(nb=nb, resources=resources, km=km, **kwargs).execute()
  File "/Users/kashnitskiyy/opt/anaconda3/envs/mlcourse/lib/python3.8/site-packages/nbclient/util.py", line 84, in wrapped
    return just_run(coro(*args, **kwargs))
  File "/Users/kashnitskiyy/opt/anaconda3/envs/mlcourse/lib/python3.8/site-packages/nbclient/util.py", line 62, in just_run
    return loop.run_until_complete(coro)
  File "/Users/kashnitskiyy/opt/anaconda3/envs/mlcourse/lib/python3.8/asyncio/base_events.py", line 616, in run_until_complete
    return future.result()
  File "/Users/kashnitskiyy/opt/anaconda3/envs/mlcourse/lib/python3.8/site-packages/nbclient/client.py", line 559, in async_execute
    await self.async_execute_cell(
  File "/Users/kashnitskiyy/opt/anaconda3/envs/mlcourse/lib/python3.8/site-packages/nbclient/client.py", line 854, in async_execute_cell
    self._check_raise_for_error(cell, exec_reply)
  File "/Users/kashnitskiyy/opt/anaconda3/envs/mlcourse/lib/python3.8/site-packages/nbclient/client.py", line 756, in _check_raise_for_error
    raise CellExecutionError.from_cell_and_msg(cell, exec_reply_content)
nbclient.exceptions.CellExecutionError: An error occurred while executing the following cell:
------------------
FILE_URL = "https://archive.ics.uci.edu/ml/machine-learning-databases/00240/UCI%20HAR%20Dataset.zip"
FILE_NAME = "UCI HAR Dataset.zip"
DATA_PATH = Path("../../../data/large_files")

load_har_dataset(url=FILE_URL, extract_path=DATA_PATH, filename=FILE_NAME)

PATH_TO_SAMSUNG_DATA = DATA_PATH / FILE_NAME.strip('.zip')
------------------

[0;31m---------------------------------------------------------------------------[0m
[0;31mFileNotFoundError[0m                         Traceback (most recent call last)
[0;32m/var/folders/xs/x4nxtnxd4qq06sg5z0x951q1q7mkqq/T/ipykernel_93851/2794252603.py[0m in [0;36m<module>[0;34m[0m
[1;32m      3[0m [0mDATA_PATH[0m [0;34m=[0m [0mPath[0m[0;34m([0m[0;34m"../../../data/large_files"[0m[0;34m)[0m[0;34m[0m[0;34m[0m[0m
[1;32m      4[0m [0;34m[0m[0m
[0;32m----> 5[0;31m [0mload_har_dataset[0m[0;34m([0m[0murl[0m[0;34m=[0m[0mFILE_URL[0m[0;34m,[0m [0mextract_path[0m[0;34m=[0m[0mDATA_PATH[0m[0;34m,[0m [0mfilename[0m[0;34m=[0m[0mFILE_NAME[0m[0;34m)[0m[0;34m[0m[0;34m[0m[0m
[0m[1;32m      6[0m [0;34m[0m[0m
[1;32m      7[0m [0mPATH_TO_SAMSUNG_DATA[0m [0;34m=[0m [0mDATA_PATH[0m [0;34m/[0m [0mFILE_NAME[0m[0;34m.[0m[0mstrip[0m[0;34m([0m[0;34m'.zip'[0m[0;34m)[0m[0;34m[0m[0;34m[0m[0m

[0;32m/var/folders/xs/x4nxtnxd4qq06sg5z0x951q1q7mkqq/T/ipykernel_93851/1106836570.py[0m in [0;36mload_har_dataset[0;34m(url, extract_path, filename, overwrite)[0m
[1;32m      9[0m     [0mresponse[0m [0;34m=[0m [0mrequests[0m[0;34m.[0m[0mget[0m[0;34m([0m[0murl[0m[0;34m)[0m[0;34m[0m[0;34m[0m[0m
[1;32m     10[0m [0;34m[0m[0m
[0;32m---> 11[0;31m     [0;32mwith[0m [0mopen[0m[0;34m([0m[0mfilepath[0m[0;34m,[0m [0;34m'wb'[0m[0;34m)[0m [0;32mas[0m [0mf[0m[0;34m:[0m[0;34m[0m[0;34m[0m[0m
[0m[1;32m     12[0m         [0mf[0m[0;34m.[0m[0mwrite[0m[0;34m([0m[0mresponse[0m[0;34m.[0m[0mcontent[0m[0;34m)[0m[0;34m[0m[0;34m[0m[0m
[1;32m     13[0m [0;34m[0m[0m

[0;31mFileNotFoundError[0m: [Errno 2] No such file or directory: '../../../data/large_files/UCI HAR Dataset.zip'
FileNotFoundError: [Errno 2] No such file or directory: '../../../data/large_files/UCI HAR Dataset.zip'

