Traceback (most recent call last):
  File "/Library/Frameworks/Python.framework/Versions/3.10/lib/python3.10/site-packages/jupyter_cache/executors/utils.py", line 51, in single_nb_execution
    executenb(
  File "/Library/Frameworks/Python.framework/Versions/3.10/lib/python3.10/site-packages/nbclient/client.py", line 1204, in execute
    return NotebookClient(nb=nb, resources=resources, km=km, **kwargs).execute()
  File "/Library/Frameworks/Python.framework/Versions/3.10/lib/python3.10/site-packages/nbclient/util.py", line 84, in wrapped
    return just_run(coro(*args, **kwargs))
  File "/Library/Frameworks/Python.framework/Versions/3.10/lib/python3.10/site-packages/nbclient/util.py", line 62, in just_run
    return loop.run_until_complete(coro)
  File "/Library/Frameworks/Python.framework/Versions/3.10/lib/python3.10/asyncio/base_events.py", line 646, in run_until_complete
    return future.result()
  File "/Library/Frameworks/Python.framework/Versions/3.10/lib/python3.10/site-packages/nbclient/client.py", line 663, in async_execute
    await self.async_execute_cell(
  File "/Library/Frameworks/Python.framework/Versions/3.10/lib/python3.10/site-packages/nbclient/client.py", line 965, in async_execute_cell
    await self._check_raise_for_error(cell, cell_index, exec_reply)
  File "/Library/Frameworks/Python.framework/Versions/3.10/lib/python3.10/site-packages/nbclient/client.py", line 862, in _check_raise_for_error
    raise CellExecutionError.from_cell_and_msg(cell, exec_reply_content)
nbclient.exceptions.CellExecutionError: An error occurred while executing the following cell:
------------------
with open(os.path.join(PATH_TO_WRITE_DATA, "20news_test_predictions.txt")) as pred_file:
    test_prediction = [float(label) for label in pred_file.readlines()]

auc = roc_auc_score(test_labels, test_prediction)
roc_curve = roc_curve(test_labels, test_prediction)

with plt.xkcd():
    plt.plot(roc_curve[0], roc_curve[1])
    plt.plot([0, 1], [0, 1])
    plt.xlabel("FPR")
    plt.ylabel("TPR")
    plt.title("test AUC = %f" % (auc))
    plt.axis([-0.05, 1.05, -0.05, 1.05]);
------------------

[0;31m---------------------------------------------------------------------------[0m
[0;31mFileNotFoundError[0m                         Traceback (most recent call last)
Input [0;32mIn [31][0m, in [0;36m<cell line: 1>[0;34m()[0m
[0;32m----> 1[0m [38;5;28;01mwith[39;00m [38;5;28;43mopen[39;49m[43m([49m[43mos[49m[38;5;241;43m.[39;49m[43mpath[49m[38;5;241;43m.[39;49m[43mjoin[49m[43m([49m[43mPATH_TO_WRITE_DATA[49m[43m,[49m[43m [49m[38;5;124;43m"[39;49m[38;5;124;43m20news_test_predictions.txt[39;49m[38;5;124;43m"[39;49m[43m)[49m[43m)[49m [38;5;28;01mas[39;00m pred_file:
[1;32m      2[0m     test_prediction [38;5;241m=[39m [[38;5;28mfloat[39m(label) [38;5;28;01mfor[39;00m label [38;5;129;01min[39;00m pred_file[38;5;241m.[39mreadlines()]
[1;32m      4[0m auc [38;5;241m=[39m roc_auc_score(test_labels, test_prediction)

[0;31mFileNotFoundError[0m: [Errno 2] No such file or directory: '../../../data/tmp/20news_test_predictions.txt'
FileNotFoundError: [Errno 2] No such file or directory: '../../../data/tmp/20news_test_predictions.txt'

