Traceback (most recent call last):
  File "/Users/kashnitskiyy/Library/Caches/pypoetry/virtualenvs/mlcourse-ai-hdQs52Zw-py3.10/lib/python3.10/site-packages/jupyter_cache/executors/utils.py", line 51, in single_nb_execution
    executenb(
  File "/Users/kashnitskiyy/Library/Caches/pypoetry/virtualenvs/mlcourse-ai-hdQs52Zw-py3.10/lib/python3.10/site-packages/nbclient/client.py", line 1204, in execute
    return NotebookClient(nb=nb, resources=resources, km=km, **kwargs).execute()
  File "/Users/kashnitskiyy/Library/Caches/pypoetry/virtualenvs/mlcourse-ai-hdQs52Zw-py3.10/lib/python3.10/site-packages/nbclient/util.py", line 84, in wrapped
    return just_run(coro(*args, **kwargs))
  File "/Users/kashnitskiyy/Library/Caches/pypoetry/virtualenvs/mlcourse-ai-hdQs52Zw-py3.10/lib/python3.10/site-packages/nbclient/util.py", line 62, in just_run
    return loop.run_until_complete(coro)
  File "/usr/local/Cellar/python@3.10/3.10.8/Frameworks/Python.framework/Versions/3.10/lib/python3.10/asyncio/base_events.py", line 649, in run_until_complete
    return future.result()
  File "/Users/kashnitskiyy/Library/Caches/pypoetry/virtualenvs/mlcourse-ai-hdQs52Zw-py3.10/lib/python3.10/site-packages/nbclient/client.py", line 663, in async_execute
    await self.async_execute_cell(
  File "/Users/kashnitskiyy/Library/Caches/pypoetry/virtualenvs/mlcourse-ai-hdQs52Zw-py3.10/lib/python3.10/site-packages/nbclient/client.py", line 965, in async_execute_cell
    await self._check_raise_for_error(cell, cell_index, exec_reply)
  File "/Users/kashnitskiyy/Library/Caches/pypoetry/virtualenvs/mlcourse-ai-hdQs52Zw-py3.10/lib/python3.10/site-packages/nbclient/client.py", line 862, in _check_raise_for_error
    raise CellExecutionError.from_cell_and_msg(cell, exec_reply_content)
nbclient.exceptions.CellExecutionError: An error occurred while executing the following cell:
------------------
print(cv.get_feature_names()[:50])
print(cv.get_feature_names()[50000:50050])
------------------

[0;31m---------------------------------------------------------------------------[0m
[0;31mAttributeError[0m                            Traceback (most recent call last)
Cell [0;32mIn[12], line 1[0m
[0;32m----> 1[0m [38;5;28mprint[39m([43mcv[49m[38;5;241;43m.[39;49m[43mget_feature_names[49m()[:[38;5;241m50[39m])
[1;32m      2[0m [38;5;28mprint[39m(cv[38;5;241m.[39mget_feature_names()[[38;5;241m50000[39m:[38;5;241m50050[39m])

[0;31mAttributeError[0m: 'CountVectorizer' object has no attribute 'get_feature_names'
AttributeError: 'CountVectorizer' object has no attribute 'get_feature_names'

