Traceback (most recent call last):
  File "/Users/kashnitskiyy/opt/anaconda3/lib/python3.8/site-packages/jupyter_cache/executors/utils.py", line 51, in single_nb_execution
    executenb(
  File "/Users/kashnitskiyy/opt/anaconda3/lib/python3.8/site-packages/nbclient/client.py", line 1112, in execute
    return NotebookClient(nb=nb, resources=resources, km=km, **kwargs).execute()
  File "/Users/kashnitskiyy/opt/anaconda3/lib/python3.8/site-packages/nbclient/util.py", line 74, in wrapped
    return just_run(coro(*args, **kwargs))
  File "/Users/kashnitskiyy/opt/anaconda3/lib/python3.8/site-packages/nbclient/util.py", line 53, in just_run
    return loop.run_until_complete(coro)
  File "/Users/kashnitskiyy/opt/anaconda3/lib/python3.8/asyncio/base_events.py", line 616, in run_until_complete
    return future.result()
  File "/Users/kashnitskiyy/opt/anaconda3/lib/python3.8/site-packages/nbclient/client.py", line 553, in async_execute
    await self.async_execute_cell(
  File "/Users/kashnitskiyy/opt/anaconda3/lib/python3.8/site-packages/nbclient/client.py", line 857, in async_execute_cell
    self._check_raise_for_error(cell, exec_reply)
  File "/Users/kashnitskiyy/opt/anaconda3/lib/python3.8/site-packages/nbclient/client.py", line 760, in _check_raise_for_error
    raise CellExecutionError.from_cell_and_msg(cell, exec_reply_content)
nbclient.exceptions.CellExecutionError: An error occurred while executing the following cell:
------------------
FILE_URL = 'https://drive.google.com/uc?id=1KbBdJaEY8RF4GXzoihWgH0RdqoVBZ_oi'
FILE_NAME = 'train-balanced-sarcasm.csv.zip'
DATA_PATH = '../../_static/data/'

download_file_from_gdrive(file_url=FILE_URL, filename= FILE_NAME, out_path=DATA_PATH)

train_df = pd.read_csv(DATA_PATH / "train-balanced-sarcasm.csv.zip")
------------------

[0;31m---------------------------------------------------------------------------[0m
[0;31mTypeError[0m                                 Traceback (most recent call last)
[0;32m<ipython-input-3-ba0830765ab0>[0m in [0;36m<module>[0;34m[0m
[1;32m      5[0m [0mdownload_file_from_gdrive[0m[0;34m([0m[0mfile_url[0m[0;34m=[0m[0mFILE_URL[0m[0;34m,[0m [0mfilename[0m[0;34m=[0m [0mFILE_NAME[0m[0;34m,[0m [0mout_path[0m[0;34m=[0m[0mDATA_PATH[0m[0;34m)[0m[0;34m[0m[0;34m[0m[0m
[1;32m      6[0m [0;34m[0m[0m
[0;32m----> 7[0;31m [0mtrain_df[0m [0;34m=[0m [0mpd[0m[0;34m.[0m[0mread_csv[0m[0;34m([0m[0mDATA_PATH[0m [0;34m/[0m [0;34m"train-balanced-sarcasm.csv.zip"[0m[0;34m)[0m[0;34m[0m[0;34m[0m[0m
[0m
[0;31mTypeError[0m: unsupported operand type(s) for /: 'str' and 'str'
TypeError: unsupported operand type(s) for /: 'str' and 'str'

